Workbook

Sheet Bilan Annuel 2026
A1: RETOUR GAGNANT BENIN — BILAN FINANCIER ANNUEL 2026
A2: IFU : 3202644573981 | RCCM : RB/COT/26 B 42001 | Donnees consolidees depuis les 12 feuilles mensuelles
A4: LEGENDE : Texte VERT = donnee liee depuis feuille mois | Fond JAUNE = cellule a saisir | Texte NOIR = formule
B6: MOIS | C6: RECETTES HT | D6: RECETTES TTC | E6: DEPENSES HT | F6: DEPENSES TTC | G6: TVA NETTE | H6: RESULTAT NET HT | I6: MARGE %
A7: 1 | B7: Janvier | C7: =Janvier!G28 -> 0 | D7: =Janvier!I28 -> 0 | E7: =Janvier!G62 -> 794406 | F7: =Janvier!I62 -> 1732476.1 | G7: =Janvier!G28*0.18-Janvier!G62*0.18 -> -142993.08 | H7: =Janvier!G28-Janvier!G62 -> -794406 | I7: =IFERROR((Janvier!G28-Janvier!G62)/Janvier!G28,0) -> 0
A8: 2 | B8: Fevrier | C8: =Fevrier!G28 -> 0 | D8: =Fevrier!I28 -> 0 | E8: =Fevrier!G70 -> 712039 | F8: =Fevrier!I70 -> 3658606.4 | G8: =Fevrier!G28*0.18-Fevrier!G70*0.18 -> -128167.02 | H8: =Fevrier!G28-Fevrier!G70 -> -712039 | I8: =IFERROR((Fevrier!G28-Fevrier!G70)/Fevrier!G28,0) -> 0
A9: 3 | B9: Mars | C9: =Mars!G28 -> 0 | D9: =Mars!I28 -> 0 | E9: =Mars!G62 -> 746058 | F9: =Mars!I62 -> 1182265.4 | G9: =Mars!G28*0.18-Mars!G62*0.18 -> -134290.44 | H9: =Mars!G28-Mars!G62 -> -746058 | I9: =IFERROR((Mars!G28-Mars!G62)/Mars!G28,0) -> 0
A10: 4 | B10: Avril | C10: =Avril!G28 -> 0 | D10: =Avril!I28 -> 0 | E10: =Avril!G62 -> 113092 | F10: =Avril!I62 -> 1320760.6 | G10: =Avril!G28*0.18-Avril!G62*0.18 -> -20356.56 | H10: =Avril!G28-Avril!G62 -> -113092 | I10: =IFERROR((Avril!G28-Avril!G62)/Avril!G28,0) -> 0
A11: 5 | B11: Mai | C11: =Mai!G28 -> 0 | D11: =Mai!I28 -> 0 | E11: =Mai!G62 -> 0 | F11: =Mai!I62 -> 0 | G11: =Mai!G28*0.18-Mai!G62*0.18 -> 0 | H11: =Mai!G28-Mai!G62 -> 0 | I11: =IFERROR((Mai!G28-Mai!G62)/Mai!G28,0) -> 0
A12: 6 | B12: Juin | C12: =Juin!G28 -> 0 | D12: =Juin!I28 -> 0 | E12: =Juin!G62 -> 0 | F12: =Juin!I62 -> 0 | G12: =Juin!G28*0.18-Juin!G62*0.18 -> 0 | H12: =Juin!G28-Juin!G62 -> 0 | I12: =IFERROR((Juin!G28-Juin!G62)/Juin!G28,0) -> 0
A13: 7 | B13: Juillet | C13: =Juillet!G28 -> 0 | D13: =Juillet!I28 -> 0 | E13: =Juillet!G62 -> 0 | F13: =Juillet!I62 -> 0 | G13: =Juillet!G28*0.18-Juillet!G62*0.18 -> 0 | H13: =Juillet!G28-Juillet!G62 -> 0 | I13: =IFERROR((Juillet!G28-Juillet!G62)/Juillet!G28,0) -> 0
A14: 8 | B14: Aout | C14: =Aout!G28 -> 0 | D14: =Aout!I28 -> 0 | E14: =Aout!G62 -> 0 | F14: =Aout!I62 -> 0 | G14: =Aout!G28*0.18-Aout!G62*0.18 -> 0 | H14: =Aout!G28-Aout!G62 -> 0 | I14: =IFERROR((Aout!G28-Aout!G62)/Aout!G28,0) -> 0
A15: 9 | B15: Septembre | C15: =Septembre!G28 -> 0 | D15: =Septembre!I28 -> 0 | E15: =Septembre!G62 -> 0 | F15: =Septembre!I62 -> 0 | G15: =Septembre!G28*0.18-Septembre!G62*0.18 -> 0 | H15: =Septembre!G28-Septembre!G62 -> 0 | I15: =IFERROR((Septembre!G28-Septembre!G62)/Septembre!G28,0) -> 0
A16: 10 | B16: Octobre | C16: =Octobre!G28 -> 0 | D16: =Octobre!I28 -> 0 | E16: =Octobre!G62 -> 0 | F16: =Octobre!I62 -> 0 | G16: =Octobre!G28*0.18-Octobre!G62*0.18 -> 0 | H16: =Octobre!G28-Octobre!G62 -> 0 | I16: =IFERROR((Octobre!G28-Octobre!G62)/Octobre!G28,0) -> 0
A17: 11 | B17: Novembre | C17: =Novembre!G28 -> 0 | D17: =Novembre!I28 -> 0 | E17: =Novembre!G62 -> 0 | F17: =Novembre!I62 -> 0 | G17: =Novembre!G28*0.18-Novembre!G62*0.18 -> 0 | H17: =Novembre!G28-Novembre!G62 -> 0 | I17: =IFERROR((Novembre!G28-Novembre!G62)/Novembre!G28,0) -> 0
A18: 12 | B18: Decembre | C18: =Decembre!G28 -> 0 | D18: =Decembre!I28 -> 0 | E18: =Decembre!G62 -> 0 | F18: =Decembre!I62 -> 0 | G18: =Decembre!G28*0.18-Decembre!G62*0.18 -> 0 | H18: =Decembre!G28-Decembre!G62 -> 0 | I18: =IFERROR((Decembre!G28-Decembre!G62)/Decembre!G28,0) -> 0
A19: TOTAL ANNUEL 2026 | C19: =SUM(C7:C18) -> 0 | D19: =SUM(D7:D18) -> 0 | E19: =SUM(E7:E18) -> 2365595 | F19: =SUM(F7:F18) -> 7894108.5 | G19: =SUM(G7:G18) -> -425807.1 | H19: =SUM(H7:H18) -> -2365595 | I19: =IFERROR(H19/C19,0) -> 0
A22: INDICATEURS CLES DE PERFORMANCE (KPI)
A23: Meilleur mois — recettes HT | F23: =INDEX(B7:B18,MATCH(MAX(C7:C18),C7:C18,0)) -> Janvier
A24: Mois le plus charge — depenses HT | F24: =INDEX(B7:B18,MATCH(MAX(E7:E18),E7:E18,0)) -> Janvier
A25: Recette mensuelle moyenne HT | F25: =AVERAGE(C7:C18) -> 0
A26: Depense mensuelle moyenne HT | F26: =AVERAGE(E7:E18) -> 197132.92
A27: TVA totale collectee sur l annee | F27: =C19*0.18 -> 0
A28: TVA totale deductible | F28: =E19*0.18 -> 425807.1
A29: TVA nette annuelle a reverser DGI | F29: =G19 -> -425807.1
A30: Resultat net annuel HT | F30: =H19 -> -2365595
A31: Taux de marge annuelle | F31: =I19 -> 0
A32: Nb mois excedentaires | F32: =COUNTIF(H7:H18,">0") -> 0
A33: Nb mois deficitaires | F33: =COUNTIF(H7:H18,"<0") -> 4
A36: GUIDE D'UTILISATION
A37: Etape 1 | C37: Aller sur la feuille du mois (Janvier, Fevrier…)
A38: Etape 2 | C38: SECTION 1 (fond vert) : saisir chaque RECETTE — date, N facture, client, categorie, montant HT
A39: Etape 3 | C39: SECTION 2 (fond rouge) : saisir chaque DEPENSE — date, N facture, fournisseur, categorie, montant HT
A40: Etape 4 | C40: TVA (col H) et TTC (col I) se calculent AUTOMATIQUEMENT depuis le taux parametre en haut
A41: Etape 5 | C41: Cliquer sur la cellule Categorie ou Statut pour choisir dans la LISTE DEROULANTE
A42: Etape 6 | C42: Ventilation par categorie et bilan se mettent a jour en temps reel
A43: Etape 7 | C43: Ce bilan annuel consolide les 12 mois automatiquement (vert = lien inter-feuilles)
A44: Etape 8 | C44: JAUNE = a saisir | BLEU = valeur saisie | NOIR = formule automatique
A45: Etape 9 | C45: TVA nette = a declarer avant le 15 du mois suivant a la DGI Benin
A46: Etape 10 | C46: Ne jamais supprimer une facture annulee — mettre statut ANNULEE

Sheet Janvier
A1: RETOUR GAGNANT BENIN — REGISTRE FACTURES • JANVIER 2026
A2: IFU : 3202644573981 | RCCM : RB/COT/26 B 42001 | Haie-Vive Cocotiers, Carre 1158, Cotonou
A4: LEGENDE : Fond JAUNE = a SAISIR | Texte BLEU = valeur saisie | Texte NOIR = formule automatique
A6: PARAMETRE TVA (taux) : | E6: 0.18 | F6: Modifier si exoneration TVA (mettre 0%)
A8: SECTION 1 — RECETTES (ENTREES)
A9: N | B9: DATE | C9: N FACTURE / RECU | D9: CLIENT / BENEFICIAIRE | E9: CATEGORIE | F9: REF. DOSSIER | G9: MONTANT HT (FCFA) | H9: TVA (auto) | I9: TTC (auto) | J9: STATUT
A10: 1 | H10: =IF(G10="","-",G10*$E$6) -> - | I10: =IF(G10="","-",G10+H10) -> -
A11: 2 | H11: =IF(G11="","-",G11*$E$6) -> - | I11: =IF(G11="","-",G11+H11) -> -
A12: 3 | H12: =IF(G12="","-",G12*$E$6) -> - | I12: =IF(G12="","-",G12+H12) -> -
A13: 4 | H13: =IF(G13="","-",G13*$E$6) -> - | I13: =IF(G13="","-",G13+H13) -> -
A14: 5 | H14: =IF(G14="","-",G14*$E$6) -> - | I14: =IF(G14="","-",G14+H14) -> -
A15: 6 | H15: =IF(G15="","-",G15*$E$6) -> - | I15: =IF(G15="","-",G15+H15) -> -
A16: 7 | H16: =IF(G16="","-",G16*$E$6) -> - | I16: =IF(G16="","-",G16+H16) -> -
A17: 8 | H17: =IF(G17="","-",G17*$E$6) -> - | I17: =IF(G17="","-",G17+H17) -> -
A18: 9 | H18: =IF(G18="","-",G18*$E$6) -> - | I18: =IF(G18="","-",G18+H18) -> -
A19: 10 | H19: =IF(G19="","-",G19*$E$6) -> - | I19: =IF(G19="","-",G19+H19) -> -
A20: 11 | H20: =IF(G20="","-",G20*$E$6) -> - | I20: =IF(G20="","-",G20+H20) -> -
A21: 12 | H21: =IF(G21="","-",G21*$E$6) -> - | I21: =IF(G21="","-",G21+H21) -> -
... A27: 18 | H27: =IF(G27="","-",G27*$E$6) -> - | I27: =IF(G27="","-",G27+H27) -> -
A28: SOUS-TOTAL RECETTES DU MOIS | G28: =SUM(G10:G27) -> 0 | H28: =SUM(H10:H27) -> 0 | I28: =SUM(I10:I27) -> 0
A30: VENTILATION RECETTES PAR CATEGORIE
A31: CATEGORIE | E31: NB FAC. | F31: TOTAL HT | H31: TOTAL TTC | J31: % TOTAL
A32: Accompagnement diaspora | E32: =COUNTIF(E10:E27,A32) -> 0 | F32: =SUMIF(E10:E27,A32,G10:G27) -> 0 | H32: =SUMIF(E10:E27,A32,I10:I27) -> 0 | J32: =IFERROR(F32/G28,0) -> 0
A33: Ceremonie du Nom | E33: =COUNTIF(E10:E27,A33) -> 0 | F33: =SUMIF(E10:E27,A33,G10:G27) -> 0 | H33: =SUMIF(E10:E27,A33,I10:I27) -> 0 | J33: =IFERROR(F33/G28,0) -> 0
A34: Commission partenaire | E34: =COUNTIF(E10:E27,A34) -> 0 | F34: =SUMIF(E10:E27,A34,G10:G27) -> 0 | H34: =SUMIF(E10:E27,A34,I10:I27) -> 0 | J34: =IFERROR(F34/G28,0) -> 0
A35: Partenariat institutionnel | E35: =COUNTIF(E10:E27,A35) -> 0 | F35: =SUMIF(E10:E27,A35,G10:G27) -> 0 | H35: =SUMIF(E10:E27,A35,I10:I27) -> 0 | J35: =IFERROR(F35/G28,0) -> 0
A36: Formation / Atelier | E36: =COUNTIF(E10:E27,A36) -> 0 | F36: =SUMIF(E10:E27,A36,G10:G27) -> 0 | H36: =SUMIF(E10:E27,A36,I10:I27) -> 0 | J36: =IFERROR(F36/G28,0) -> 0
A37: Location / Prestation | E37: =COUNTIF(E10:E27,A37) -> 0 | F37: =SUMIF(E10:E27,A37,G10:G27) -> 0 | H37: =SUMIF(E10:E27,A37,I10:I27) -> 0 | J37: =IFERROR(F37/G28,0) -> 0
A38: Subvention / Aide | E38: =COUNTIF(E10:E27,A38) -> 0 | F38: =SUMIF(E10:E27,A38,G10:G27) -> 0 | H38: =SUMIF(E10:E27,A38,I10:I27) -> 0 | J38: =IFERROR(F38/G28,0) -> 0
A39: Autre recette | E39: =COUNTIF(E10:E27,A39) -> 0 | F39: =SUMIF(E10:E27,A39,G10:G27) -> 0 | H39: =SUMIF(E10:E27,A39,I10:I27) -> 0 | J39: =IFERROR(F39/G28,0) -> 0
A42: SECTION 2 — DEPENSES (SORTIES)
A43: N | B43: DATE | C43: N FACTURE / RECU | D43: FOURNISSEUR | E43: CATEGORIE | F43: REF. | G43: MONTANT HT (FCFA) | H43: TVA (auto) | I43: TTC (auto) | J43: STATUT
A44: 1 | B44: 46027 | C44: 20100807651FB | D44: SONEB | E44: Loyer et charges | H44: =IF(G44="","-",G44*$E$6) -> - | I44: 1409 | J44: PAYEE
A45: 2 | B45: 46049 | C45: 167902 | D45: MIKEM TECHNOLOGIE | E45: Fournitures bureau | G45: 794406 | H45: =IF(G45="","-",G45*$E$6) -> 142993.08 | I45: =IF(G45="","-",G45+H45) -> 937399.08 | J45: PAYEE
A46: 3 | B46: 46024 | C46: FACAEROP26010032 | D46: MOOV AFRICA | E46: Telephone et Internet | H46: =IF(G46="","-",G46*$E$6) -> - | I46: 148000 | J46: PAYEE
A47: 4 | B47: 46033 | C47: 003409 | D47: LE DILLON | E47: Autre depense | H47: =IF(G47="","-",G47*$E$6) -> - | I47: 6000 | J47: PAYEE
A48: 5 | B48: 46024 | C48: 239540635729CO | D48: SGDS | E48: Loyer et charges | H48: =IF(G48="","-",G48*$E$6) -> - | I48: 120000 | J48: EN ATTENTE
A49: 6 | B49: 46023 | C49: 0000127 | D49: LOUECARS | E49: Deplacement et carburant | H49: =IF(G49="","-",G49*$E$6) -> - | I49: 500000 | J49: PAYEE
A50: 7 | B50: 45931 | C50: 396955 | D50: CNSS | E50: Salaires et charges | H50: =IF(G50="","-",G50*$E$6) -> - | I50: 2000 | J50: PAYEE
A51: 8 | B51: 46027 | C51: 3244414 | D51: SBEE | E51: Loyer et charges | H51: =IF(G51="","-",G51*$E$6) -> - | I51: 5868 | J51: PAYEE
...

Sheet Fevrier
A1: RETOUR GAGNANT BENIN — REGISTRE FACTURES • FEVRIER 2026
A2: IFU : 3202644573981 | RCCM : RB/COT/26 B 42001 | Haie-Vive Cocotiers, Carre 1158, Cotonou
A4: LEGENDE : Fond JAUNE = a SAISIR | Texte BLEU = valeur saisie | Texte NOIR = formule automatique
A6: PARAMETRE TVA (taux) : | E6: 0.18 | F6: Modifier si exoneration TVA (mettre 0%)
A8: SECTION 1 — RECETTES (ENTREES)
A9: N | B9: DATE | C9: N FACTURE / RECU | D9: CLIENT / BENEFICIAIRE | E9: CATEGORIE | F9: REF. DOSSIER | G9: MONTANT HT (FCFA) | H9: TVA (auto) | I9: TTC (auto) | J9: STATUT
A10: 1 | H10: =IF(G10="","-",G10*$E$6) -> - | I10: =IF(G10="","-",G10+H10) -> -
A11: 2 | H11: =IF(G11="","-",G11*$E$6) -> - | I11: =IF(G11="","-",G11+H11) -> -
A12: 3 | H12: =IF(G12="","-",G12*$E$6) -> - | I12: =IF(G12="","-",G12+H12) -> -
A13: 4 | H13: =IF(G13="","-",G13*$E$6) -> - | I13: =IF(G13="","-",G13+H13) -> -
A14: 5 | H14: =IF(G14="","-",G14*$E$6) -> - | I14: =IF(G14="","-",G14+H14) -> -
A15: 6 | H15: =IF(G15="","-",G15*$E$6) -> - | I15: =IF(G15="","-",G15+H15) -> -
A16: 7 | H16: =IF(G16="","-",G16*$E$6) -> - | I16: =IF(G16="","-",G16+H16) -> -
A17: 8 | H17: =IF(G17="","-",G17*$E$6) -> - | I17: =IF(G17="","-",G17+H17) -> -
A18: 9 | H18: =IF(G18="","-",G18*$E$6) -> - | I18: =IF(G18="","-",G18+H18) -> -
A19: 10 | H19: =IF(G19="","-",G19*$E$6) -> - | I19: =IF(G19="","-",G19+H19) -> -
A20: 11 | H20: =IF(G20="","-",G20*$E$6) -> - | I20: =IF(G20="","-",G20+H20) -> -
A21: 12 | H21: =IF(G21="","-",G21*$E$6) -> - | I21: =IF(G21="","-",G21+H21) -> -
... A27: 18 | H27: =IF(G27="","-",G27*$E$6) -> - | I27: =IF(G27="","-",G27+H27) -> -
A28: SOUS-TOTAL RECETTES DU MOIS | G28: =SUM(G10:G27) -> 0 | H28: =SUM(H10:H27) -> 0 | I28: =SUM(I10:I27) -> 0
A30: VENTILATION RECETTES PAR CATEGORIE
A31: CATEGORIE | E31: NB FAC. | F31: TOTAL HT | H31: TOTAL TTC | J31: % TOTAL
A32: Accompagnement diaspora | E32: =COUNTIF(E10:E27,A32) -> 0 | F32: =SUMIF(E10:E27,A32,G10:G27) -> 0 | H32: =SUMIF(E10:E27,A32,I10:I27) -> 0 | J32: =IFERROR(F32/G28,0) -> 0
A33: Ceremonie du Nom | E33: =COUNTIF(E10:E27,A33) -> 0 | F33: =SUMIF(E10:E27,A33,G10:G27) -> 0 | H33: =SUMIF(E10:E27,A33,I10:I27) -> 0 | J33: =IFERROR(F33/G28,0) -> 0
A34: Commission partenaire | E34: =COUNTIF(E10:E27,A34) -> 0 | F34: =SUMIF(E10:E27,A34,G10:G27) -> 0 | H34: =SUMIF(E10:E27,A34,I10:I27) -> 0 | J34: =IFERROR(F34/G28,0) -> 0
A35: Partenariat institutionnel | E35: =COUNTIF(E10:E27,A35) -> 0 | F35: =SUMIF(E10:E27,A35,G10:G27) -> 0 | H35: =SUMIF(E10:E27,A35,I10:I27) -> 0 | J35: =IFERROR(F35/G28,0) -> 0
A36: Formation / Atelier | E36: =COUNTIF(E10:E27,A36) -> 0 | F36: =SUMIF(E10:E27,A36,G10:G27) -> 0 | H36: =SUMIF(E10:E27,A36,I10:I27) -> 0 | J36: =IFERROR(F36/G28,0) -> 0
A37: Location / Prestation | E37: =COUNTIF(E10:E27,A37) -> 0 | F37: =SUMIF(E10:E27,A37,G10:G27) -> 0 | H37: =SUMIF(E10:E27,A37,I10:I27) -> 0 | J37: =IFERROR(F37/G28,0) -> 0
A38: Subvention / Aide | E38: =COUNTIF(E10:E27,A38) -> 0 | F38: =SUMIF(E10:E27,A38,G10:G27) -> 0 | H38: =SUMIF(E10:E27,A38,I10:I27) -> 0 | J38: =IFERROR(F38/G28,0) -> 0
A39: Autre recette | E39: =COUNTIF(E10:E27,A39) -> 0 | F39: =SUMIF(E10:E27,A39,G10:G27) -> 0 | H39: =SUMIF(E10:E27,A39,I10:I27) -> 0 | J39: =IFERROR(F39/G28,0) -> 0
A42: SECTION 2 — DEPENSES (SORTIES)
A43: N | B43: DATE | C43: N FACTURE / RECU | D43: FOURNISSEUR | E43: CATEGORIE | F43: REF. | G43: MONTANT HT (FCFA) | H43: TVA (auto) | I43: TTC (auto) | J43: STATUT
A44: 1 | B44: 46071 | C44: 0000166 | D44: MAFNIFIQUE MEUBLES | E44: Fournitures bureau | H44: =IF(G44="","-",G44*$E$6) -> - | I44: 230000 | J44: PAYEE
A45: 2 | B45: 46069 | C45: 000189 | D45: YAMOUTOUGOU & FILS | E45: Fournitures bureau | H45: =IF(G45="","-",G45*$E$6) -> - | I45: 280000 | J45: PAYEE
A46: 3 | B46: 46069 | E46: Fournitures bureau | H46: =IF(G46="","-",G46*$E$6) -> - | I46: 60000 | J46: PAYEE
A47: 4 | B47: 46066 | C47: FACAEROP2602306 | D47: MOOV AFRICA | E47: Communication et Pub | H47: =IF(G47="","-",G47*$E$6) -> - | I47: 12000 | J47: PAYEE
A48: 5 | B48: 46069 | E48: Fournitures bureau | H48: =IF(G48="","-",G48*$E$6) -> - | I48: 120000 | J48: PAYEE
A49: 6 | B49: 46069 | E49: Fournitures bureau | H49: =IF(G49="","-",G49*$E$6) -> - | I49: 7000 | J49: PAYEE
A50: 7 | B50: 46067 | C50: CC235883 | D50: SONAEC | E50: Fournitures bureau | G50: 203226 | H50: =IF(G50="","-",G50*$E$6) -> 36580.68 | I50: =IF(G50="","-",G50+H50) -> 239806.68 | J50: PAYEE
A51: 8 | B51: 46069 | C51: 56536/CHILL AND GRILL/16022026/503439 | D51: CHILL AND GRILL | E51: Autre depense | H51: =IF(G51="","-",G51*$E$6) -> - | I51: 10500 | J51: PAYEE
...

Sheet Mars
A1: RETOUR GAGNANT BENIN — REGISTRE FACTURES • MARS 2026
A2: IFU : 3202644573981 | RCCM : RB/COT/26 B 42001 | Haie-Vive Cocotiers, Carre 1158, Cotonou
A4: LEGENDE : Fond JAUNE = a SAISIR | Texte BLEU = valeur saisie | Texte NOIR = formule automatique
A6: PARAMETRE TVA (taux) : | E6: 0.18 | F6: Modifier si exoneration TVA (mettre 0%)
A8: SECTION 1 — RECETTES (ENTREES)
A9: N | B9: DATE | C9: N FACTURE / RECU | D9: CLIENT / BENEFICIAIRE | E9: CATEGORIE | F9: REF. DOSSIER | G9: MONTANT HT (FCFA) | H9: TVA (auto) | I9: TTC (auto) | J9: STATUT
A10: 1 | H10: =IF(G10="","-",G10*$E$6) -> - | I10: =IF(G10="","-",G10+H10) -> -
A11: 2 | H11: =IF(G11="","-",G11*$E$6) -> - | I11: =IF(G11="","-",G11+H11) -> -
A12: 3 | H12: =IF(G12="","-",G12*$E$6) -> - | I12: =IF(G12="","-",G12+H12) -> -
A13: 4 | H13: =IF(G13="","-",G13*$E$6) -> - | I13: =IF(G13="","-",G13+H13) -> -
A14: 5 | H14: =IF(G14="","-",G14*$E$6) -> - | I14: =IF(G14="","-",G14+H14) -> -
A15: 6 | H15: =IF(G15="","-",G15*$E$6) -> - | I15: =IF(G15="","-",G15+H15) -> -
A16: 7 | H16: =IF(G16="","-",G16*$E$6) -> - | I16: =IF(G16="","-",G16+H16) -> -
A17: 8 | H17: =IF(G17="","-",G17*$E$6) -> - | I17: =IF(G17="","-",G17+H17) -> -
A18: 9 | H18: =IF(G18="","-",G18*$E$6) -> - | I18: =IF(G18="","-",G18+H18) -> -
A19: 10 | H19: =IF(G19="","-",G19*$E$6) -> - | I19: =IF(G19="","-",G19+H19) -> -
A20: 11 | H20: =IF(G20="","-",G20*$E$6) -> - | I20: =IF(G20="","-",G20+H20) -> -
A21: 12 | H21: =IF(G21="","-",G21*$E$6) -> - | I21: =IF(G21="","-",G21+H21) -> -
... A27: 18 | H27: =IF(G27="","-",G27*$E$6) -> - | I27: =IF(G27="","-",G27+H27) -> -
A28: SOUS-TOTAL RECETTES DU MOIS | G28: =SUM(G10:G27) -> 0 | H28: =SUM(H10:H27) -> 0 | I28: =SUM(I10:I27) -> 0
A30: VENTILATION RECETTES PAR CATEGORIE
A31: CATEGORIE | E31: NB FAC. | F31: TOTAL HT | H31: TOTAL TTC | J31: % TOTAL
A32: Accompagnement diaspora | E32: =COUNTIF(E10:E27,A32) -> 0 | F32: =SUMIF(E10:E27,A32,G10:G27) -> 0 | H32: =SUMIF(E10:E27,A32,I10:I27) -> 0 | J32: =IFERROR(F32/G28,0) -> 0
A33: Ceremonie du Nom | E33: =COUNTIF(E10:E27,A33) -> 0 | F33: =SUMIF(E10:E27,A33,G10:G27) -> 0 | H33: =SUMIF(E10:E27,A33,I10:I27) -> 0 | J33: =IFERROR(F33/G28,0) -> 0
A34: Commission partenaire | E34: =COUNTIF(E10:E27,A34) -> 0 | F34: =SUMIF(E10:E27,A34,G10:G27) -> 0 | H34: =SUMIF(E10:E27,A34,I10:I27) -> 0 | J34: =IFERROR(F34/G28,0) -> 0
A35: Partenariat institutionnel | E35: =COUNTIF(E10:E27,A35) -> 0 | F35: =SUMIF(E10:E27,A35,G10:G27) -> 0 | H35: =SUMIF(E10:E27,A35,I10:I27) -> 0 | J35: =IFERROR(F35/G28,0) -> 0
A36: Formation / Atelier | E36: =COUNTIF(E10:E27,A36) -> 0 | F36: =SUMIF(E10:E27,A36,G10:G27) -> 0 | H36: =SUMIF(E10:E27,A36,I10:I27) -> 0 | J36: =IFERROR(F36/G28,0) -> 0
A37: Location / Prestation | E37: =COUNTIF(E10:E27,A37) -> 0 | F37: =SUMIF(E10:E27,A37,G10:G27) -> 0 | H37: =SUMIF(E10:E27,A37,I10:I27) -> 0 | J37: =IFERROR(F37/G28,0) -> 0
A38: Subvention / Aide | E38: =COUNTIF(E10:E27,A38) -> 0 | F38: =SUMIF(E10:E27,A38,G10:G27) -> 0 | H38: =SUMIF(E10:E27,A38,I10:I27) -> 0 | J38: =IFERROR(F38/G28,0) -> 0
A39: Autre recette | E39: =COUNTIF(E10:E27,A39) -> 0 | F39: =SUMIF(E10:E27,A39,G10:G27) -> 0 | H39: =SUMIF(E10:E27,A39,I10:I27) -> 0 | J39: =IFERROR(F39/G28,0) -> 0
A42: SECTION 2 — DEPENSES (SORTIES)
A43: N | B43: DATE | C43: N FACTURE / RECU | D43: FOURNISSEUR | E43: CATEGORIE | F43: REF. | G43: MONTANT HT (FCFA) | H43: TVA (auto) | I43: TTC (auto) | J43: STATUT
A44: 1 | B44: 46108 | C44: K0002875984 | D44: SBIN | E44: Communication et Pub | H44: =IF(G44="","-",G44*$E$6) -> - | I44: 11567 | J44: PAYEE
A45: 2 | B45: 46107 | C45: 24660 | D45: SOLEIL | E45: Autre depense | G45: 23686 | H45: =IF(G45="","-",G45*$E$6) -> 4263.48 | I45: =IF(G45="","-",G45+H45) -> 27949.48 | J45: PAYEE
A46: 3 | B46: 46107 | C46: 57198/CHILL AND GRILL/26032026/510687 | D46: RESTAURANT CHILL AND GRILL | E46: Autre depense | H46: =IF(G46="","-",G46*$E$6) -> - | I46: 18000 | J46: PAYEE
A47: 4 | B47: 46109 | C47: 202600248289 | D47: EREVAN | E47: Autre depense | H47: =IF(G47="","-",G47*$E$6) -> - | I47: =40410 -> 40410 | J47: PAYEE
A48: 5 | B48: 46109 | C48: 21503 | D48: EMINENCE PRO | E48: Autre depense | H48: =IF(G48="","-",G48*$E$6) -> - | I48: 30003 | J48: PAYEE
A49: 6 | B49: 46110 | C49: 132200005507 | D49: FAO ET FILS SERVICES | E49: Deplacement et carburant | H49: =IF(G49="","-",G49*$E$6) -> - | I49: 32500 | J49: PAYEE
A50: 7 | B50: 46109 | C50: 001493015862 | D50: ECOBANK | E50: Frais bancaires | H50: =IF(G50="","-",G50*$E$6) -> - | I50: 25000 | J50: PAYEE
A51: 8 | B51: 46105 | C51: ED04001324 | D51: ORCA DECO | E51: Materiel et equipement | G51: 127119 | H51: =IF(G51="","-",G51*$E$6) -> 22881.42 | I51: =IF(G51="","-",G51+H51) -> 150000.42 | J51: PAYEE
...

Sheet Avril
A1: RETOUR GAGNANT BENIN — REGISTRE FACTURES • AVRIL 2026
A2: IFU : 3202644573981 | RCCM : RB/COT/26 B 42001 | Haie-Vive Cocotiers, Carre 1158, Cotonou
A4: LEGENDE : Fond JAUNE = a SAISIR | Texte BLEU = valeur saisie | Texte NOIR = formule automatique
A6: PARAMETRE TVA (taux) : | E6: 0.18 | F6: Modifier si exoneration TVA (mettre 0%)
A8: SECTION 1 — RECETTES (ENTREES)
A9: N | B9: DATE | C9: N FACTURE / RECU | D9: CLIENT / BENEFICIAIRE | E9: CATEGORIE | F9: REF. DOSSIER | G9: MONTANT HT (FCFA) | H9: TVA (auto) | I9: TTC (auto) | J9: STATUT
A10: 1 | H10: =IF(G10="","-",G10*$E$6) -> - | I10: =IF(G10="","-",G10+H10) -> -
A11: 2 | H11: =IF(G11="","-",G11*$E$6) -> - | I11: =IF(G11="","-",G11+H11) -> -
A12: 3 | H12: =IF(G12="","-",G12*$E$6) -> - | I12: =IF(G12="","-",G12+H12) -> -
A13: 4 | H13: =IF(G13="","-",G13*$E$6) -> - | I13: =IF(G13="","-",G13+H13) -> -
A14: 5 | H14: =IF(G14="","-",G14*$E$6) -> - | I14: =IF(G14="","-",G14+H14) -> -
A15: 6 | H15: =IF(G15="","-",G15*$E$6) -> - | I15: =IF(G15="","-",G15+H15) -> -
A16: 7 | H16: =IF(G16="","-",G16*$E$6) -> - | I16: =IF(G16="","-",G16+H16) -> -
A17: 8 | H17: =IF(G17="","-",G17*$E$6) -> - | I17: =IF(G17="","-",G17+H17) -> -
A18: 9 | H18: =IF(G18="","-",G18*$E$6) -> - | I18: =IF(G18="","-",G18+H18) -> -
A19: 10 | H19: =IF(G19="","-",G19*$E$6) -> - | I19: =IF(G19="","-",G19+H19) -> -
A20: 11 | H20: =IF(G20="","-",G20*$E$6) -> - | I20: =IF(G20="","-",G20+H20) -> -
A21: 12 | H21: =IF(G21="","-",G21*$E$6) -> - | I21: =IF(G21="","-",G21+H21) -> -
... A27: 18 | H27: =IF(G27="","-",G27*$E$6) -> - | I27: =IF(G27="","-",G27+H27) -> -
A28: SOUS-TOTAL RECETTES DU MOIS | G28: =SUM(G10:G27) -> 0 | H28: =SUM(H10:H27) -> 0 | I28: =SUM(I10:I27) -> 0
A30: VENTILATION RECETTES PAR CATEGORIE
A31: CATEGORIE | E31: NB FAC. | F31: TOTAL HT | H31: TOTAL TTC | J31: % TOTAL
A32: Accompagnement diaspora | E32: =COUNTIF(E10:E27,A32) -> 0 | F32: =SUMIF(E10:E27,A32,G10:G27) -> 0 | H32: =SUMIF(E10:E27,A32,I10:I27) -> 0 | J32: =IFERROR(F32/G28,0) -> 0
A33: Ceremonie du Nom | E33: =COUNTIF(E10:E27,A33) -> 0 | F33: =SUMIF(E10:E27,A33,G10:G27) -> 0 | H33: =SUMIF(E10:E27,A33,I10:I27) -> 0 | J33: =IFERROR(F33/G28,0) -> 0
A34: Commission partenaire | E34: =COUNTIF(E10:E27,A34) -> 0 | F34: =SUMIF(E10:E27,A34,G10:G27) -> 0 | H34: =SUMIF(E10:E27,A34,I10:I27) -> 0 | J34: =IFERROR(F34/G28,0) -> 0
A35: Partenariat institutionnel | E35: =COUNTIF(E10:E27,A35) -> 0 | F35: =SUMIF(E10:E27,A35,G10:G27) -> 0 | H35: =SUMIF(E10:E27,A35,I10:I27) -> 0 | J35: =IFERROR(F35/G28,0) -> 0
A36: Formation / Atelier | E36: =COUNTIF(E10:E27,A36) -> 0 | F36: =SUMIF(E10:E27,A36,G10:G27) -> 0 | H36: =SUMIF(E10:E27,A36,I10:I27) -> 0 | J36: =IFERROR(F36/G28,0) -> 0
A37: Location / Prestation | E37: =COUNTIF(E10:E27,A37) -> 0 | F37: =SUMIF(E10:E27,A37,G10:G27) -> 0 | H37: =SUMIF(E10:E27,A37,I10:I27) -> 0 | J37: =IFERROR(F37/G28,0) -> 0
A38: Subvention / Aide | E38: =COUNTIF(E10:E27,A38) -> 0 | F38: =SUMIF(E10:E27,A38,G10:G27) -> 0 | H38: =SUMIF(E10:E27,A38,I10:I27) -> 0 | J38: =IFERROR(F38/G28,0) -> 0
A39: Autre recette | E39: =COUNTIF(E10:E27,A39) -> 0 | F39: =SUMIF(E10:E27,A39,G10:G27) -> 0 | H39: =SUMIF(E10:E27,A39,I10:I27) -> 0 | J39: =IFERROR(F39/G28,0) -> 0
A42: SECTION 2 — DEPENSES (SORTIES)
A43: N | B43: DATE | C43: N FACTURE / RECU | D43: FOURNISSEUR | E43: CATEGORIE | F43: REF. | G43: MONTANT HT (FCFA) | H43: TVA (auto) | I43: TTC (auto) | J43: STATUT
A44: 1 | B44: 46127 | C44: 2076755 | D44: SBEE | E44: Loyer et charges | H44: =IF(G44="","-",G44*$E$6) -> - | I44: 14865 | J44: PAYEE
A45: 2 | B45: 46127 | C45: 2016746 | D45: SBEE | E45: Loyer et charges | H45: =IF(G45="","-",G45*$E$6) -> - | I45: 107447 | J45: PAYEE
A46: 3 | B46: 46114 | C46: 11817859678 | D46: Alphone SOSSA | E46: Communication et Pub | H46: =IF(G46="","-",G46*$E$6) -> - | I46: 40000 | J46: PAYEE
A47: 4 | B47: 46126 | C47: EM01022664-21 | D47: WABI | E47: Fournitures bureau | H47: =IF(G47="","-",G47*$E$6) -> - | I47: 500000 | J47: PAYEE
A48: 5 | B48: 46122 | C48: FP202604101 | D48: AIT TECHNOLOGY | E48: Fournitures bureau | H48: =IF(G48="","-",G48*$E$6) -> - | I48: 525000 | J48: EN ATTENTE
A49: 6 | B49: 46127 | C49: 202600016443 | D49: EREVAN | E49: Fournitures bureau | G49: 113092 | H49: =IF(G49="","-",G49*$E$6) -> 20356.56 | I49: =IF(G49="","-",G49+H49) -> 133448.56 | J49: PAYEE
A50: 7 | H50: =IF(G50="","-",G50*$E$6) -> - | I50: =IF(G50="","-",G50+H50) -> -
A51: 8 | H51: =IF(G51="","-",G51*$E$6) -> - | I51: =IF(G51="","-",G51+H51) -> -
...

Sheet Mai
A1: RETOUR GAGNANT BENIN — REGISTRE FACTURES • MAI 2026
A2: IFU : 3202644573981 | RCCM : RB/COT/26 B 42001 | Haie-Vive Cocotiers, Carre 1158, Cotonou
A4: LEGENDE : Fond JAUNE = a SAISIR | Texte BLEU = valeur saisie | Texte NOIR = formule automatique
A6: PARAMETRE TVA (taux) : | E6: 0.18 | F6: Modifier si exoneration TVA (mettre 0%)
A8: SECTION 1 — RECETTES (ENTREES)
A9: N | B9: DATE | C9: N FACTURE / RECU | D9: CLIENT / BENEFICIAIRE | E9: CATEGORIE | F9: REF. DOSSIER | G9: MONTANT HT (FCFA) | H9: TVA (auto) | I9: TTC (auto) | J9: STATUT
A10: 1 | H10: =IF(G10="","-",G10*$E$6) -> - | I10: =IF(G10="","-",G10+H10) -> -
A11: 2 | H11: =IF(G11="","-",G11*$E$6) -> - | I11: =IF(G11="","-",G11+H11) -> -
A12: 3 | H12: =IF(G12="","-",G12*$E$6) -> - | I12: =IF(G12="","-",G12+H12) -> -
A13: 4 | H13: =IF(G13="","-",G13*$E$6) -> - | I13: =IF(G13="","-",G13+H13) -> -
A14: 5 | H14: =IF(G14="","-",G14*$E$6) -> - | I14: =IF(G14="","-",G14+H14) -> -
A15: 6 | H15: =IF(G15="","-",G15*$E$6) -> - | I15: =IF(G15="","-",G15+H15) -> -
A16: 7 | H16: =IF(G16="","-",G16*$E$6) -> - | I16: =IF(G16="","-",G16+H16) -> -
A17: 8 | H17: =IF(G17="","-",G17*$E$6) -> - | I17: =IF(G17="","-",G17+H17) -> -
A18: 9 | H18: =IF(G18="","-",G18*$E$6) -> - | I18: =IF(G18="","-",G18+H18) -> -
A19: 10 | H19: =IF(G19="","-",G19*$E$6) -> - | I19: =IF(G19="","-",G19+H19) -> -
A20: 11 | H20: =IF(G20="","-",G20*$E$6) -> - | I20: =IF(G20="","-",G20+H20) -> -
A21: 12 | H21: =IF(G21="","-",G21*$E$6) -> - | I21: =IF(G21="","-",G21+H21) -> -
... A27: 18 | H27: =IF(G27="","-",G27*$E$6) -> - | I27: =IF(G27="","-",G27+H27) -> -
A28: SOUS-TOTAL RECETTES DU MOIS | G28: =SUM(G10:G27) -> 0 | H28: =SUM(H10:H27) -> 0 | I28: =SUM(I10:I27) -> 0
A30: VENTILATION RECETTES PAR CATEGORIE
A31: CATEGORIE | E31: NB FAC. | F31: TOTAL HT | H31: TOTAL TTC | J31: % TOTAL
A32: Accompagnement diaspora | E32: =COUNTIF(E10:E27,A32) -> 0 | F32: =SUMIF(E10:E27,A32,G10:G27) -> 0 | H32: =SUMIF(E10:E27,A32,I10:I27) -> 0 | J32: =IFERROR(F32/G28,0) -> 0
A33: Ceremonie du Nom | E33: =COUNTIF(E10:E27,A33) -> 0 | F33: =SUMIF(E10:E27,A33,G10:G27) -> 0 | H33: =SUMIF(E10:E27,A33,I10:I27) -> 0 | J33: =IFERROR(F33/G28,0) -> 0
A34: Commission partenaire | E34: =COUNTIF(E10:E27,A34) -> 0 | F34: =SUMIF(E10:E27,A34,G10:G27) -> 0 | H34: =SUMIF(E10:E27,A34,I10:I27) -> 0 | J34: =IFERROR(F34/G28,0) -> 0
A35: Partenariat institutionnel | E35: =COUNTIF(E10:E27,A35) -> 0 | F35: =SUMIF(E10:E27,A35,G10:G27) -> 0 | H35: =SUMIF(E10:E27,A35,I10:I27) -> 0 | J35: =IFERROR(F35/G28,0) -> 0
A36: Formation / Atelier | E36: =COUNTIF(E10:E27,A36) -> 0 | F36: =SUMIF(E10:E27,A36,G10:G27) -> 0 | H36: =SUMIF(E10:E27,A36,I10:I27) -> 0 | J36: =IFERROR(F36/G28,0) -> 0
A37: Location / Prestation | E37: =COUNTIF(E10:E27,A37) -> 0 | F37: =SUMIF(E10:E27,A37,G10:G27) -> 0 | H37: =SUMIF(E10:E27,A37,I10:I27) -> 0 | J37: =IFERROR(F37/G28,0) -> 0
A38: Subvention / Aide | E38: =COUNTIF(E10:E27,A38) -> 0 | F38: =SUMIF(E10:E27,A38,G10:G27) -> 0 | H38: =SUMIF(E10:E27,A38,I10:I27) -> 0 | J38: =IFERROR(F38/G28,0) -> 0
A39: Autre recette | E39: =COUNTIF(E10:E27,A39) -> 0 | F39: =SUMIF(E10:E27,A39,G10:G27) -> 0 | H39: =SUMIF(E10:E27,A39,I10:I27) -> 0 | J39: =IFERROR(F39/G28,0) -> 0
A42: SECTION 2 — DEPENSES (SORTIES)
A43: N | B43: DATE | C43: N FACTURE / RECU | D43: FOURNISSEUR | E43: CATEGORIE | F43: REF. | G43: MONTANT HT (FCFA) | H43: TVA (auto) | I43: TTC (auto) | J43: STATUT
A44: 1 | H44: =IF(G44="","-",G44*$E$6) -> - | I44: =IF(G44="","-",G44+H44) -> -
A45: 2 | H45: =IF(G45="","-",G45*$E$6) -> - | I45: =IF(G45="","-",G45+H45) -> -
A46: 3 | H46: =IF(G46="","-",G46*$E$6) -> - | I46: =IF(G46="","-",G46+H46) -> -
A47: 4 | H47: =IF(G47="","-",G47*$E$6) -> - | I47: =IF(G47="","-",G47+H47) -> -
A48: 5 | H48: =IF(G48="","-",G48*$E$6) -> - | I48: =IF(G48="","-",G48+H48) -> -
A49: 6 | H49: =IF(G49="","-",G49*$E$6) -> - | I49: =IF(G49="","-",G49+H49) -> -
A50: 7 | H50: =IF(G50="","-",G50*$E$6) -> - | I50: =IF(G50="","-",G50+H50) -> -
A51: 8 | H51: =IF(G51="","-",G51*$E$6) -> - | I51: =IF(G51="","-",G51+H51) -> -
...

Sheet Juin
A1: RETOUR GAGNANT BENIN — REGISTRE FACTURES • JUIN 2026
A2: IFU : 3202644573981 | RCCM : RB/COT/26 B 42001 | Haie-Vive Cocotiers, Carre 1158, Cotonou
A4: LEGENDE : Fond JAUNE = a SAISIR | Texte BLEU = valeur saisie | Texte NOIR = formule automatique
A6: PARAMETRE TVA (taux) : | E6: 0.18 | F6: Modifier si exoneration TVA (mettre 0%)
A8: SECTION 1 — RECETTES (ENTREES)
A9: N | B9: DATE | C9: N FACTURE / RECU | D9: CLIENT / BENEFICIAIRE | E9: CATEGORIE | F9: REF. DOSSIER | G9: MONTANT HT (FCFA) | H9: TVA (auto) | I9: TTC (auto) | J9: STATUT
A10: 1 | H10: =IF(G10="","-",G10*$E$6) -> - | I10: =IF(G10="","-",G10+H10) -> -
A11: 2 | H11: =IF(G11="","-",G11*$E$6) -> - | I11: =IF(G11="","-",G11+H11) -> -
A12: 3 | H12: =IF(G12="","-",G12*$E$6) -> - | I12: =IF(G12="","-",G12+H12) -> -
A13: 4 | H13: =IF(G13="","-",G13*$E$6) -> - | I13: =IF(G13="","-",G13+H13) -> -
A14: 5 | H14: =IF(G14="","-",G14*$E$6) -> - | I14: =IF(G14="","-",G14+H14) -> -
A15: 6 | H15: =IF(G15="","-",G15*$E$6) -> - | I15: =IF(G15="","-",G15+H15) -> -
A16: 7 | H16: =IF(G16="","-",G16*$E$6) -> - | I16: =IF(G16="","-",G16+H16) -> -
A17: 8 | H17: =IF(G17="","-",G17*$E$6) -> - | I17: =IF(G17="","-",G17+H17) -> -
A18: 9 | H18: =IF(G18="","-",G18*$E$6) -> - | I18: =IF(G18="","-",G18+H18) -> -
A19: 10 | H19: =IF(G19="","-",G19*$E$6) -> - | I19: =IF(G19="","-",G19+H19) -> -
A20: 11 | H20: =IF(G20="","-",G20*$E$6) -> - | I20: =IF(G20="","-",G20+H20) -> -
A21: 12 | H21: =IF(G21="","-",G21*$E$6) -> - | I21: =IF(G21="","-",G21+H21) -> -
... A27: 18 | H27: =IF(G27="","-",G27*$E$6) -> - | I27: =IF(G27="","-",G27+H27) -> -
A28: SOUS-TOTAL RECETTES DU MOIS | G28: =SUM(G10:G27) -> 0 | H28: =SUM(H10:H27) -> 0 | I28: =SUM(I10:I27) -> 0
A30: VENTILATION RECETTES PAR CATEGORIE
A31: CATEGORIE | E31: NB FAC. | F31: TOTAL HT | H31: TOTAL TTC | J31: % TOTAL
A32: Accompagnement diaspora | E32: =COUNTIF(E10:E27,A32) -> 0 | F32: =SUMIF(E10:E27,A32,G10:G27) -> 0 | H32: =SUMIF(E10:E27,A32,I10:I27) -> 0 | J32: =IFERROR(F32/G28,0) -> 0
A33: Ceremonie du Nom | E33: =COUNTIF(E10:E27,A33) -> 0 | F33: =SUMIF(E10:E27,A33,G10:G27) -> 0 | H33: =SUMIF(E10:E27,A33,I10:I27) -> 0 | J33: =IFERROR(F33/G28,0) -> 0
A34: Commission partenaire | E34: =COUNTIF(E10:E27,A34) -> 0 | F34: =SUMIF(E10:E27,A34,G10:G27) -> 0 | H34: =SUMIF(E10:E27,A34,I10:I27) -> 0 | J34: =IFERROR(F34/G28,0) -> 0
A35: Partenariat institutionnel | E35: =COUNTIF(E10:E27,A35) -> 0 | F35: =SUMIF(E10:E27,A35,G10:G27) -> 0 | H35: =SUMIF(E10:E27,A35,I10:I27) -> 0 | J35: =IFERROR(F35/G28,0) -> 0
A36: Formation / Atelier | E36: =COUNTIF(E10:E27,A36) -> 0 | F36: =SUMIF(E10:E27,A36,G10:G27) -> 0 | H36: =SUMIF(E10:E27,A36,I10:I27) -> 0 | J36: =IFERROR(F36/G28,0) -> 0
A37: Location / Prestation | E37: =COUNTIF(E10:E27,A37) -> 0 | F37: =SUMIF(E10:E27,A37,G10:G27) -> 0 | H37: =SUMIF(E10:E27,A37,I10:I27) -> 0 | J37: =IFERROR(F37/G28,0) -> 0
A38: Subvention / Aide | E38: =COUNTIF(E10:E27,A38) -> 0 | F38: =SUMIF(E10:E27,A38,G10:G27) -> 0 | H38: =SUMIF(E10:E27,A38,I10:I27) -> 0 | J38: =IFERROR(F38/G28,0) -> 0
A39: Autre recette | E39: =COUNTIF(E10:E27,A39) -> 0 | F39: =SUMIF(E10:E27,A39,G10:G27) -> 0 | H39: =SUMIF(E10:E27,A39,I10:I27) -> 0 | J39: =IFERROR(F39/G28,0) -> 0
A42: SECTION 2 — DEPENSES (SORTIES)
A43: N | B43: DATE | C43: N FACTURE / RECU | D43: FOURNISSEUR | E43: CATEGORIE | F43: REF. | G43: MONTANT HT (FCFA) | H43: TVA (auto) | I43: TTC (auto) | J43: STATUT
A44: 1 | H44: =IF(G44="","-",G44*$E$6) -> - | I44: =IF(G44="","-",G44+H44) -> -
A45: 2 | H45: =IF(G45="","-",G45*$E$6) -> - | I45: =IF(G45="","-",G45+H45) -> -
A46: 3 | H46: =IF(G46="","-",G46*$E$6) -> - | I46: =IF(G46="","-",G46+H46) -> -
A47: 4 | H47: =IF(G47="","-",G47*$E$6) -> - | I47: =IF(G47="","-",G47+H47) -> -
A48: 5 | H48: =IF(G48="","-",G48*$E$6) -> - | I48: =IF(G48="","-",G48+H48) -> -
A49: 6 | H49: =IF(G49="","-",G49*$E$6) -> - | I49: =IF(G49="","-",G49+H49) -> -
A50: 7 | H50: =IF(G50="","-",G50*$E$6) -> - | I50: =IF(G50="","-",G50+H50) -> -
A51: 8 | H51: =IF(G51="","-",G51*$E$6) -> - | I51: =IF(G51="","-",G51+H51) -> -
...

Sheet Juillet
A1: RETOUR GAGNANT BENIN — REGISTRE FACTURES • JUILLET 2026
A2: IFU : 3202644573981 | RCCM : RB/COT/26 B 42001 | Haie-Vive Cocotiers, Carre 1158, Cotonou
A4: LEGENDE : Fond JAUNE = a SAISIR | Texte BLEU = valeur saisie | Texte NOIR = formule automatique
A6: PARAMETRE TVA (taux) : | E6: 0.18 | F6: Modifier si exoneration TVA (mettre 0%)
A8: SECTION 1 — RECETTES (ENTREES)
A9: N | B9: DATE | C9: N FACTURE / RECU | D9: CLIENT / BENEFICIAIRE | E9: CATEGORIE | F9: REF. DOSSIER | G9: MONTANT HT (FCFA) | H9: TVA (auto) | I9: TTC (auto) | J9: STATUT
A10: 1 | H10: =IF(G10="","-",G10*$E$6) -> - | I10: =IF(G10="","-",G10+H10) -> -
A11: 2 | H11: =IF(G11="","-",G11*$E$6) -> - | I11: =IF(G11="","-",G11+H11) -> -
A12: 3 | H12: =IF(G12="","-",G12*$E$6) -> - | I12: =IF(G12="","-",G12+H12) -> -
A13: 4 | H13: =IF(G13="","-",G13*$E$6) -> - | I13: =IF(G13="","-",G13+H13) -> -
A14: 5 | H14: =IF(G14="","-",G14*$E$6) -> - | I14: =IF(G14="","-",G14+H14) -> -
A15: 6 | H15: =IF(G15="","-",G15*$E$6) -> - | I15: =IF(G15="","-",G15+H15) -> -
A16: 7 | H16: =IF(G16="","-",G16*$E$6) -> - | I16: =IF(G16="","-",G16+H16) -> -
A17: 8 | H17: =IF(G17="","-",G17*$E$6) -> - | I17: =IF(G17="","-",G17+H17) -> -
A18: 9 | H18: =IF(G18="","-",G18*$E$6) -> - | I18: =IF(G18="","-",G18+H18) -> -
A19: 10 | H19: =IF(G19="","-",G19*$E$6) -> - | I19: =IF(G19="","-",G19+H19) -> -
A20: 11 | H20: =IF(G20="","-",G20*$E$6) -> - | I20: =IF(G20="","-",G20+H20) -> -
A21: 12 | H21: =IF(G21="","-",G21*$E$6) -> - | I21: =IF(G21="","-",G21+H21) -> -
... A27: 18 | H27: =IF(G27="","-",G27*$E$6) -> - | I27: =IF(G27="","-",G27+H27) -> -
A28: SOUS-TOTAL RECETTES DU MOIS | G28: =SUM(G10:G27) -> 0 | H28: =SUM(H10:H27) -> 0 | I28: =SUM(I10:I27) -> 0
A30: VENTILATION RECETTES PAR CATEGORIE
A31: CATEGORIE | E31: NB FAC. | F31: TOTAL HT | H31: TOTAL TTC | J31: % TOTAL
A32: Accompagnement diaspora | E32: =COUNTIF(E10:E27,A32) -> 0 | F32: =SUMIF(E10:E27,A32,G10:G27) -> 0 | H32: =SUMIF(E10:E27,A32,I10:I27) -> 0 | J32: =IFERROR(F32/G28,0) -> 0
A33: Ceremonie du Nom | E33: =COUNTIF(E10:E27,A33) -> 0 | F33: =SUMIF(E10:E27,A33,G10:G27) -> 0 | H33: =SUMIF(E10:E27,A33,I10:I27) -> 0 | J33: =IFERROR(F33/G28,0) -> 0
A34: Commission partenaire | E34: =COUNTIF(E10:E27,A34) -> 0 | F34: =SUMIF(E10:E27,A34,G10:G27) -> 0 | H34: =SUMIF(E10:E27,A34,I10:I27) -> 0 | J34: =IFERROR(F34/G28,0) -> 0
A35: Partenariat institutionnel | E35: =COUNTIF(E10:E27,A35) -> 0 | F35: =SUMIF(E10:E27,A35,G10:G27) -> 0 | H35: =SUMIF(E10:E27,A35,I10:I27) -> 0 | J35: =IFERROR(F35/G28,0) -> 0
A36: Formation / Atelier | E36: =COUNTIF(E10:E27,A36) -> 0 | F36: =SUMIF(E10:E27,A36,G10:G27) -> 0 | H36: =SUMIF(E10:E27,A36,I10:I27) -> 0 | J36: =IFERROR(F36/G28,0) -> 0
A37: Location / Prestation | E37: =COUNTIF(E10:E27,A37) -> 0 | F37: =SUMIF(E10:E27,A37,G10:G27) -> 0 | H37: =SUMIF(E10:E27,A37,I10:I27) -> 0 | J37: =IFERROR(F37/G28,0) -> 0
A38: Subvention / Aide | E38: =COUNTIF(E10:E27,A38) -> 0 | F38: =SUMIF(E10:E27,A38,G10:G27) -> 0 | H38: =SUMIF(E10:E27,A38,I10:I27) -> 0 | J38: =IFERROR(F38/G28,0) -> 0
A39: Autre recette | E39: =COUNTIF(E10:E27,A39) -> 0 | F39: =SUMIF(E10:E27,A39,G10:G27) -> 0 | H39: =SUMIF(E10:E27,A39,I10:I27) -> 0 | J39: =IFERROR(F39/G28,0) -> 0
A42: SECTION 2 — DEPENSES (SORTIES)
A43: N | B43: DATE | C43: N FACTURE / RECU | D43: FOURNISSEUR | E43: CATEGORIE | F43: REF. | G43: MONTANT HT (FCFA) | H43: TVA (auto) | I43: TTC (auto) | J43: STATUT
A44: 1 | H44: =IF(G44="","-",G44*$E$6) -> - | I44: =IF(G44="","-",G44+H44) -> -
A45: 2 | H45: =IF(G45="","-",G45*$E$6) -> - | I45: =IF(G45="","-",G45+H45) -> -
A46: 3 | H46: =IF(G46="","-",G46*$E$6) -> - | I46: =IF(G46="","-",G46+H46) -> -
A47: 4 | H47: =IF(G47="","-",G47*$E$6) -> - | I47: =IF(G47="","-",G47+H47) -> -
A48: 5 | H48: =IF(G48="","-",G48*$E$6) -> - | I48: =IF(G48="","-",G48+H48) -> -
A49: 6 | H49: =IF(G49="","-",G49*$E$6) -> - | I49: =IF(G49="","-",G49+H49) -> -
A50: 7 | H50: =IF(G50="","-",G50*$E$6) -> - | I50: =IF(G50="","-",G50+H50) -> -
A51: 8 | H51: =IF(G51="","-",G51*$E$6) -> - | I51: =IF(G51="","-",G51+H51) -> -
...

Sheet Aout
A1: RETOUR GAGNANT BENIN — REGISTRE FACTURES • AOUT 2026
A2: IFU : 3202644573981 | RCCM : RB/COT/26 B 42001 | Haie-Vive Cocotiers, Carre 1158, Cotonou
A4: LEGENDE : Fond JAUNE = a SAISIR | Texte BLEU = valeur saisie | Texte NOIR = formule automatique
A6: PARAMETRE TVA (taux) : | E6: 0.18 | F6: Modifier si exoneration TVA (mettre 0%)
A8: SECTION 1 — RECETTES (ENTREES)
A9: N | B9: DATE | C9: N FACTURE / RECU | D9: CLIENT / BENEFICIAIRE | E9: CATEGORIE | F9: REF. DOSSIER | G9: MONTANT HT (FCFA) | H9: TVA (auto) | I9: TTC (auto) | J9: STATUT
A10: 1 | H10: =IF(G10="","-",G10*$E$6) -> - | I10: =IF(G10="","-",G10+H10) -> -
A11: 2 | H11: =IF(G11="","-",G11*$E$6) -> - | I11: =IF(G11="","-",G11+H11) -> -
A12: 3 | H12: =IF(G12="","-",G12*$E$6) -> - | I12: =IF(G12="","-",G12+H12) -> -
A13: 4 | H13: =IF(G13="","-",G13*$E$6) -> - | I13: =IF(G13="","-",G13+H13) -> -
A14: 5 | H14: =IF(G14="","-",G14*$E$6) -> - | I14: =IF(G14="","-",G14+H14) -> -
A15: 6 | H15: =IF(G15="","-",G15*$E$6) -> - | I15: =IF(G15="","-",G15+H15) -> -
A16: 7 | H16: =IF(G16="","-",G16*$E$6) -> - | I16: =IF(G16="","-",G16+H16) -> -
A17: 8 | H17: =IF(G17="","-",G17*$E$6) -> - | I17: =IF(G17="","-",G17+H17) -> -
A18: 9 | H18: =IF(G18="","-",G18*$E$6) -> - | I18: =IF(G18="","-",G18+H18) -> -
A19: 10 | H19: =IF(G19="","-",G19*$E$6) -> - | I19: =IF(G19="","-",G19+H19) -> -
A20: 11 | H20: =IF(G20="","-",G20*$E$6) -> - | I20: =IF(G20="","-",G20+H20) -> -
A21: 12 | H21: =IF(G21="","-",G21*$E$6) -> - | I21: =IF(G21="","-",G21+H21) -> -
... A27: 18 | H27: =IF(G27="","-",G27*$E$6) -> - | I27: =IF(G27="","-",G27+H27) -> -
A28: SOUS-TOTAL RECETTES DU MOIS | G28: =SUM(G10:G27) -> 0 | H28: =SUM(H10:H27) -> 0 | I28: =SUM(I10:I27) -> 0
A30: VENTILATION RECETTES PAR CATEGORIE
A31: CATEGORIE | E31: NB FAC. | F31: TOTAL HT | H31: TOTAL TTC | J31: % TOTAL
A32: Accompagnement diaspora | E32: =COUNTIF(E10:E27,A32) -> 0 | F32: =SUMIF(E10:E27,A32,G10:G27) -> 0 | H32: =SUMIF(E10:E27,A32,I10:I27) -> 0 | J32: =IFERROR(F32/G28,0) -> 0
A33: Ceremonie du Nom | E33: =COUNTIF(E10:E27,A33) -> 0 | F33: =SUMIF(E10:E27,A33,G10:G27) -> 0 | H33: =SUMIF(E10:E27,A33,I10:I27) -> 0 | J33: =IFERROR(F33/G28,0) -> 0
A34: Commission partenaire | E34: =COUNTIF(E10:E27,A34) -> 0 | F34: =SUMIF(E10:E27,A34,G10:G27) -> 0 | H34: =SUMIF(E10:E27,A34,I10:I27) -> 0 | J34: =IFERROR(F34/G28,0) -> 0
A35: Partenariat institutionnel | E35: =COUNTIF(E10:E27,A35) -> 0 | F35: =SUMIF(E10:E27,A35,G10:G27) -> 0 | H35: =SUMIF(E10:E27,A35,I10:I27) -> 0 | J35: =IFERROR(F35/G28,0) -> 0
A36: Formation / Atelier | E36: =COUNTIF(E10:E27,A36) -> 0 | F36: =SUMIF(E10:E27,A36,G10:G27) -> 0 | H36: =SUMIF(E10:E27,A36,I10:I27) -> 0 | J36: =IFERROR(F36/G28,0) -> 0
A37: Location / Prestation | E37: =COUNTIF(E10:E27,A37) -> 0 | F37: =SUMIF(E10:E27,A37,G10:G27) -> 0 | H37: =SUMIF(E10:E27,A37,I10:I27) -> 0 | J37: =IFERROR(F37/G28,0) -> 0
A38: Subvention / Aide | E38: =COUNTIF(E10:E27,A38) -> 0 | F38: =SUMIF(E10:E27,A38,G10:G27) -> 0 | H38: =SUMIF(E10:E27,A38,I10:I27) -> 0 | J38: =IFERROR(F38/G28,0) -> 0
A39: Autre recette | E39: =COUNTIF(E10:E27,A39) -> 0 | F39: =SUMIF(E10:E27,A39,G10:G27) -> 0 | H39: =SUMIF(E10:E27,A39,I10:I27) -> 0 | J39: =IFERROR(F39/G28,0) -> 0
A42: SECTION 2 — DEPENSES (SORTIES)
A43: N | B43: DATE | C43: N FACTURE / RECU | D43: FOURNISSEUR | E43: CATEGORIE | F43: REF. | G43: MONTANT HT (FCFA) | H43: TVA (auto) | I43: TTC (auto) | J43: STATUT
A44: 1 | H44: =IF(G44="","-",G44*$E$6) -> - | I44: =IF(G44="","-",G44+H44) -> -
A45: 2 | H45: =IF(G45="","-",G45*$E$6) -> - | I45: =IF(G45="","-",G45+H45) -> -
A46: 3 | H46: =IF(G46="","-",G46*$E$6) -> - | I46: =IF(G46="","-",G46+H46) -> -
A47: 4 | H47: =IF(G47="","-",G47*$E$6) -> - | I47: =IF(G47="","-",G47+H47) -> -
A48: 5 | H48: =IF(G48="","-",G48*$E$6) -> - | I48: =IF(G48="","-",G48+H48) -> -
A49: 6 | H49: =IF(G49="","-",G49*$E$6) -> - | I49: =IF(G49="","-",G49+H49) -> -
A50: 7 | H50: =IF(G50="","-",G50*$E$6) -> - | I50: =IF(G50="","-",G50+H50) -> -
A51: 8 | H51: =IF(G51="","-",G51*$E$6) -> - | I51: =IF(G51="","-",G51+H51) -> -
...

Sheet Septembre
A1: RETOUR GAGNANT BENIN — REGISTRE FACTURES • SEPTEMBRE 2026
A2: IFU : 3202644573981 | RCCM : RB/COT/26 B 42001 | Haie-Vive Cocotiers, Carre 1158, Cotonou
A4: LEGENDE : Fond JAUNE = a SAISIR | Texte BLEU = valeur saisie | Texte NOIR = formule automatique
A6: PARAMETRE TVA (taux) : | E6: 0.18 | F6: Modifier si exoneration TVA (mettre 0%)
A8: SECTION 1 — RECETTES (ENTREES)
A9: N | B9: DATE | C9: N FACTURE / RECU | D9: CLIENT / BENEFICIAIRE | E9: CATEGORIE | F9: REF. DOSSIER | G9: MONTANT HT (FCFA) | H9: TVA (auto) | I9: TTC (auto) | J9: STATUT
A10: 1 | H10: =IF(G10="","-",G10*$E$6) -> - | I10: =IF(G10="","-",G10+H10) -> -
A11: 2 | H11: =IF(G11="","-",G11*$E$6) -> - | I11: =IF(G11="","-",G11+H11) -> -
A12: 3 | H12: =IF(G12="","-",G12*$E$6) -> - | I12: =IF(G12="","-",G12+H12) -> -
A13: 4 | H13: =IF(G13="","-",G13*$E$6) -> - | I13: =IF(G13="","-",G13+H13) -> -
A14: 5 | H14: =IF(G14="","-",G14*$E$6) -> - | I14: =IF(G14="","-",G14+H14) -> -
A15: 6 | H15: =IF(G15="","-",G15*$E$6) -> - | I15: =IF(G15="","-",G15+H15) -> -
A16: 7 | H16: =IF(G16="","-",G16*$E$6) -> - | I16: =IF(G16="","-",G16+H16) -> -
A17: 8 | H17: =IF(G17="","-",G17*$E$6) -> - | I17: =IF(G17="","-",G17+H17) -> -
A18: 9 | H18: =IF(G18="","-",G18*$E$6) -> - | I18: =IF(G18="","-",G18+H18) -> -
A19: 10 | H19: =IF(G19="","-",G19*$E$6) -> - | I19: =IF(G19="","-",G19+H19) -> -
A20: 11 | H20: =IF(G20="","-",G20*$E$6) -> - | I20: =IF(G20="","-",G20+H20) -> -
A21: 12 | H21: =IF(G21="","-",G21*$E$6) -> - | I21: =IF(G21="","-",G21+H21) -> -
... A27: 18 | H27: =IF(G27="","-",G27*$E$6) -> - | I27: =IF(G27="","-",G27+H27) -> -
A28: SOUS-TOTAL RECETTES DU MOIS | G28: =SUM(G10:G27) -> 0 | H28: =SUM(H10:H27) -> 0 | I28: =SUM(I10:I27) -> 0
A30: VENTILATION RECETTES PAR CATEGORIE
A31: CATEGORIE | E31: NB FAC. | F31: TOTAL HT | H31: TOTAL TTC | J31: % TOTAL
A32: Accompagnement diaspora | E32: =COUNTIF(E10:E27,A32) -> 0 | F32: =SUMIF(E10:E27,A32,G10:G27) -> 0 | H32: =SUMIF(E10:E27,A32,I10:I27) -> 0 | J32: =IFERROR(F32/G28,0) -> 0
A33: Ceremonie du Nom | E33: =COUNTIF(E10:E27,A33) -> 0 | F33: =SUMIF(E10:E27,A33,G10:G27) -> 0 | H33: =SUMIF(E10:E27,A33,I10:I27) -> 0 | J33: =IFERROR(F33/G28,0) -> 0
A34: Commission partenaire | E34: =COUNTIF(E10:E27,A34) -> 0 | F34: =SUMIF(E10:E27,A34,G10:G27) -> 0 | H34: =SUMIF(E10:E27,A34,I10:I27) -> 0 | J34: =IFERROR(F34/G28,0) -> 0
A35: Partenariat institutionnel | E35: =COUNTIF(E10:E27,A35) -> 0 | F35: =SUMIF(E10:E27,A35,G10:G27) -> 0 | H35: =SUMIF(E10:E27,A35,I10:I27) -> 0 | J35: =IFERROR(F35/G28,0) -> 0
A36: Formation / Atelier | E36: =COUNTIF(E10:E27,A36) -> 0 | F36: =SUMIF(E10:E27,A36,G10:G27) -> 0 | H36: =SUMIF(E10:E27,A36,I10:I27) -> 0 | J36: =IFERROR(F36/G28,0) -> 0
A37: Location / Prestation | E37: =COUNTIF(E10:E27,A37) -> 0 | F37: =SUMIF(E10:E27,A37,G10:G27) -> 0 | H37: =SUMIF(E10:E27,A37,I10:I27) -> 0 | J37: =IFERROR(F37/G28,0) -> 0
A38: Subvention / Aide | E38: =COUNTIF(E10:E27,A38) -> 0 | F38: =SUMIF(E10:E27,A38,G10:G27) -> 0 | H38: =SUMIF(E10:E27,A38,I10:I27) -> 0 | J38: =IFERROR(F38/G28,0) -> 0
A39: Autre recette | E39: =COUNTIF(E10:E27,A39) -> 0 | F39: =SUMIF(E10:E27,A39,G10:G27) -> 0 | H39: =SUMIF(E10:E27,A39,I10:I27) -> 0 | J39: =IFERROR(F39/G28,0) -> 0
A42: SECTION 2 — DEPENSES (SORTIES)
A43: N | B43: DATE | C43: N FACTURE / RECU | D43: FOURNISSEUR | E43: CATEGORIE | F43: REF. | G43: MONTANT HT (FCFA) | H43: TVA (auto) | I43: TTC (auto) | J43: STATUT
A44: 1 | H44: =IF(G44="","-",G44*$E$6) -> - | I44: =IF(G44="","-",G44+H44) -> -
A45: 2 | H45: =IF(G45="","-",G45*$E$6) -> - | I45: =IF(G45="","-",G45+H45) -> -
A46: 3 | H46: =IF(G46="","-",G46*$E$6) -> - | I46: =IF(G46="","-",G46+H46) -> -
A47: 4 | H47: =IF(G47="","-",G47*$E$6) -> - | I47: =IF(G47="","-",G47+H47) -> -
A48: 5 | H48: =IF(G48="","-",G48*$E$6) -> - | I48: =IF(G48="","-",G48+H48) -> -
A49: 6 | H49: =IF(G49="","-",G49*$E$6) -> - | I49: =IF(G49="","-",G49+H49) -> -
A50: 7 | H50: =IF(G50="","-",G50*$E$6) -> - | I50: =IF(G50="","-",G50+H50) -> -
A51: 8 | H51: =IF(G51="","-",G51*$E$6) -> - | I51: =IF(G51="","-",G51+H51) -> -
...

Sheet Octobre
A1: RETOUR GAGNANT BENIN — REGISTRE FACTURES • OCTOBRE 2026
A2: IFU : 3202644573981 | RCCM : RB/COT/26 B 42001 | Haie-Vive Cocotiers, Carre 1158, Cotonou
A4: LEGENDE : Fond JAUNE = a SAISIR | Texte BLEU = valeur saisie | Texte NOIR = formule automatique
A6: PARAMETRE TVA (taux) : | E6: 0.18 | F6: Modifier si exoneration TVA (mettre 0%)
A8: SECTION 1 — RECETTES (ENTREES)
A9: N | B9: DATE | C9: N FACTURE / RECU | D9: CLIENT / BENEFICIAIRE | E9: CATEGORIE | F9: REF. DOSSIER | G9: MONTANT HT (FCFA) | H9: TVA (auto) | I9: TTC (auto) | J9: STATUT
A10: 1 | H10: =IF(G10="","-",G10*$E$6) -> - | I10: =IF(G10="","-",G10+H10) -> -
A11: 2 | H11: =IF(G11="","-",G11*$E$6) -> - | I11: =IF(G11="","-",G11+H11) -> -
A12: 3 | H12: =IF(G12="","-",G12*$E$6) -> - | I12: =IF(G12="","-",G12+H12) -> -
A13: 4 | H13: =IF(G13="","-",G13*$E$6) -> - | I13: =IF(G13="","-",G13+H13) -> -
A14: 5 | H14: =IF(G14="","-",G14*$E$6) -> - | I14: =IF(G14="","-",G14+H14) -> -
A15: 6 | H15: =IF(G15="","-",G15*$E$6) -> - | I15: =IF(G15="","-",G15+H15) -> -
A16: 7 | H16: =IF(G16="","-",G16*$E$6) -> - | I16: =IF(G16="","-",G16+H16) -> -
A17: 8 | H17: =IF(G17="","-",G17*$E$6) -> - | I17: =IF(G17="","-",G17+H17) -> -
A18: 9 | H18: =IF(G18="","-",G18*$E$6) -> - | I18: =IF(G18="","-",G18+H18) -> -
A19: 10 | H19: =IF(G19="","-",G19*$E$6) -> - | I19: =IF(G19="","-",G19+H19) -> -
A20: 11 | H20: =IF(G20="","-",G20*$E$6) -> - | I20: =IF(G20="","-",G20+H20) -> -
A21: 12 | H21: =IF(G21="","-",G21*$E$6) -> - | I21: =IF(G21="","-",G21+H21) -> -
... A27: 18 | H27: =IF(G27="","-",G27*$E$6) -> - | I27: =IF(G27="","-",G27+H27) -> -
A28: SOUS-TOTAL RECETTES DU MOIS | G28: =SUM(G10:G27) -> 0 | H28: =SUM(H10:H27) -> 0 | I28: =SUM(I10:I27) -> 0
A30: VENTILATION RECETTES PAR CATEGORIE
A31: CATEGORIE | E31: NB FAC. | F31: TOTAL HT | H31: TOTAL TTC | J31: % TOTAL
A32: Accompagnement diaspora | E32: =COUNTIF(E10:E27,A32) -> 0 | F32: =SUMIF(E10:E27,A32,G10:G27) -> 0 | H32: =SUMIF(E10:E27,A32,I10:I27) -> 0 | J32: =IFERROR(F32/G28,0) -> 0
A33: Ceremonie du Nom | E33: =COUNTIF(E10:E27,A33) -> 0 | F33: =SUMIF(E10:E27,A33,G10:G27) -> 0 | H33: =SUMIF(E10:E27,A33,I10:I27) -> 0 | J33: =IFERROR(F33/G28,0) -> 0
A34: Commission partenaire | E34: =COUNTIF(E10:E27,A34) -> 0 | F34: =SUMIF(E10:E27,A34,G10:G27) -> 0 | H34: =SUMIF(E10:E27,A34,I10:I27) -> 0 | J34: =IFERROR(F34/G28,0) -> 0
A35: Partenariat institutionnel | E35: =COUNTIF(E10:E27,A35) -> 0 | F35: =SUMIF(E10:E27,A35,G10:G27) -> 0 | H35: =SUMIF(E10:E27,A35,I10:I27) -> 0 | J35: =IFERROR(F35/G28,0) -> 0
A36: Formation / Atelier | E36: =COUNTIF(E10:E27,A36) -> 0 | F36: =SUMIF(E10:E27,A36,G10:G27) -> 0 | H36: =SUMIF(E10:E27,A36,I10:I27) -> 0 | J36: =IFERROR(F36/G28,0) -> 0
A37: Location / Prestation | E37: =COUNTIF(E10:E27,A37) -> 0 | F37: =SUMIF(E10:E27,A37,G10:G27) -> 0 | H37: =SUMIF(E10:E27,A37,I10:I27) -> 0 | J37: =IFERROR(F37/G28,0) -> 0
A38: Subvention / Aide | E38: =COUNTIF(E10:E27,A38) -> 0 | F38: =SUMIF(E10:E27,A38,G10:G27) -> 0 | H38: =SUMIF(E10:E27,A38,I10:I27) -> 0 | J38: =IFERROR(F38/G28,0) -> 0
A39: Autre recette | E39: =COUNTIF(E10:E27,A39) -> 0 | F39: =SUMIF(E10:E27,A39,G10:G27) -> 0 | H39: =SUMIF(E10:E27,A39,I10:I27) -> 0 | J39: =IFERROR(F39/G28,0) -> 0
A42: SECTION 2 — DEPENSES (SORTIES)
A43: N | B43: DATE | C43: N FACTURE / RECU | D43: FOURNISSEUR | E43: CATEGORIE | F43: REF. | G43: MONTANT HT (FCFA) | H43: TVA (auto) | I43: TTC (auto) | J43: STATUT
A44: 1 | H44: =IF(G44="","-",G44*$E$6) -> - | I44: =IF(G44="","-",G44+H44) -> -
A45: 2 | H45: =IF(G45="","-",G45*$E$6) -> - | I45: =IF(G45="","-",G45+H45) -> -
A46: 3 | H46: =IF(G46="","-",G46*$E$6) -> - | I46: =IF(G46="","-",G46+H46) -> -
A47: 4 | H47: =IF(G47="","-",G47*$E$6) -> - | I47: =IF(G47="","-",G47+H47) -> -
A48: 5 | H48: =IF(G48="","-",G48*$E$6) -> - | I48: =IF(G48="","-",G48+H48) -> -
A49: 6 | H49: =IF(G49="","-",G49*$E$6) -> - | I49: =IF(G49="","-",G49+H49) -> -
A50: 7 | H50: =IF(G50="","-",G50*$E$6) -> - | I50: =IF(G50="","-",G50+H50) -> -
A51: 8 | H51: =IF(G51="","-",G51*$E$6) -> - | I51: =IF(G51="","-",G51+H51) -> -
...

Sheet Novembre
A1: RETOUR GAGNANT BENIN — REGISTRE FACTURES • NOVEMBRE 2026
A2: IFU : 3202644573981 | RCCM : RB/COT/26 B 42001 | Haie-Vive Cocotiers, Carre 1158, Cotonou
A4: LEGENDE : Fond JAUNE = a SAISIR | Texte BLEU = valeur saisie | Texte NOIR = formule automatique
A6: PARAMETRE TVA (taux) : | E6: 0.18 | F6: Modifier si exoneration TVA (mettre 0%)
A8: SECTION 1 — RECETTES (ENTREES)
A9: N | B9: DATE | C9: N FACTURE / RECU | D9: CLIENT / BENEFICIAIRE | E9: CATEGORIE | F9: REF. DOSSIER | G9: MONTANT HT (FCFA) | H9: TVA (auto) | I9: TTC (auto) | J9: STATUT
A10: 1 | H10: =IF(G10="","-",G10*$E$6) -> - | I10: =IF(G10="","-",G10+H10) -> -
A11: 2 | H11: =IF(G11="","-",G11*$E$6) -> - | I11: =IF(G11="","-",G11+H11) -> -
A12: 3 | H12: =IF(G12="","-",G12*$E$6) -> - | I12: =IF(G12="","-",G12+H12) -> -
A13: 4 | H13: =IF(G13="","-",G13*$E$6) -> - | I13: =IF(G13="","-",G13+H13) -> -
A14: 5 | H14: =IF(G14="","-",G14*$E$6) -> - | I14: =IF(G14="","-",G14+H14) -> -
A15: 6 | H15: =IF(G15="","-",G15*$E$6) -> - | I15: =IF(G15="","-",G15+H15) -> -
A16: 7 | H16: =IF(G16="","-",G16*$E$6) -> - | I16: =IF(G16="","-",G16+H16) -> -
A17: 8 | H17: =IF(G17="","-",G17*$E$6) -> - | I17: =IF(G17="","-",G17+H17) -> -
A18: 9 | H18: =IF(G18="","-",G18*$E$6) -> - | I18: =IF(G18="","-",G18+H18) -> -
A19: 10 | H19: =IF(G19="","-",G19*$E$6) -> - | I19: =IF(G19="","-",G19+H19) -> -
A20: 11 | H20: =IF(G20="","-",G20*$E$6) -> - | I20: =IF(G20="","-",G20+H20) -> -
A21: 12 | H21: =IF(G21="","-",G21*$E$6) -> - | I21: =IF(G21="","-",G21+H21) -> -
... A27: 18 | H27: =IF(G27="","-",G27*$E$6) -> - | I27: =IF(G27="","-",G27+H27) -> -
A28: SOUS-TOTAL RECETTES DU MOIS | G28: =SUM(G10:G27) -> 0 | H28: =SUM(H10:H27) -> 0 | I28: =SUM(I10:I27) -> 0
A30: VENTILATION RECETTES PAR CATEGORIE
A31: CATEGORIE | E31: NB FAC. | F31: TOTAL HT | H31: TOTAL TTC | J31: % TOTAL
A32: Accompagnement diaspora | E32: =COUNTIF(E10:E27,A32) -> 0 | F32: =SUMIF(E10:E27,A32,G10:G27) -> 0 | H32: =SUMIF(E10:E27,A32,I10:I27) -> 0 | J32: =IFERROR(F32/G28,0) -> 0
A33: Ceremonie du Nom | E33: =COUNTIF(E10:E27,A33) -> 0 | F33: =SUMIF(E10:E27,A33,G10:G27) -> 0 | H33: =SUMIF(E10:E27,A33,I10:I27) -> 0 | J33: =IFERROR(F33/G28,0) -> 0
A34: Commission partenaire | E34: =COUNTIF(E10:E27,A34) -> 0 | F34: =SUMIF(E10:E27,A34,G10:G27) -> 0 | H34: =SUMIF(E10:E27,A34,I10:I27) -> 0 | J34: =IFERROR(F34/G28,0) -> 0
A35: Partenariat institutionnel | E35: =COUNTIF(E10:E27,A35) -> 0 | F35: =SUMIF(E10:E27,A35,G10:G27) -> 0 | H35: =SUMIF(E10:E27,A35,I10:I27) -> 0 | J35: =IFERROR(F35/G28,0) -> 0
A36: Formation / Atelier | E36: =COUNTIF(E10:E27,A36) -> 0 | F36: =SUMIF(E10:E27,A36,G10:G27) -> 0 | H36: =SUMIF(E10:E27,A36,I10:I27) -> 0 | J36: =IFERROR(F36/G28,0) -> 0
A37: Location / Prestation | E37: =COUNTIF(E10:E27,A37) -> 0 | F37: =SUMIF(E10:E27,A37,G10:G27) -> 0 | H37: =SUMIF(E10:E27,A37,I10:I27) -> 0 | J37: =IFERROR(F37/G28,0) -> 0
A38: Subvention / Aide | E38: =COUNTIF(E10:E27,A38) -> 0 | F38: =SUMIF(E10:E27,A38,G10:G27) -> 0 | H38: =SUMIF(E10:E27,A38,I10:I27) -> 0 | J38: =IFERROR(F38/G28,0) -> 0
A39: Autre recette | E39: =COUNTIF(E10:E27,A39) -> 0 | F39: =SUMIF(E10:E27,A39,G10:G27) -> 0 | H39: =SUMIF(E10:E27,A39,I10:I27) -> 0 | J39: =IFERROR(F39/G28,0) -> 0
A42: SECTION 2 — DEPENSES (SORTIES)
A43: N | B43: DATE | C43: N FACTURE / RECU | D43: FOURNISSEUR | E43: CATEGORIE | F43: REF. | G43: MONTANT HT (FCFA) | H43: TVA (auto) | I43: TTC (auto) | J43: STATUT
A44: 1 | H44: =IF(G44="","-",G44*$E$6) -> - | I44: =IF(G44="","-",G44+H44) -> -
A45: 2 | H45: =IF(G45="","-",G45*$E$6) -> - | I45: =IF(G45="","-",G45+H45) -> -
A46: 3 | H46: =IF(G46="","-",G46*$E$6) -> - | I46: =IF(G46="","-",G46+H46) -> -
A47: 4 | H47: =IF(G47="","-",G47*$E$6) -> - | I47: =IF(G47="","-",G47+H47) -> -
A48: 5 | H48: =IF(G48="","-",G48*$E$6) -> - | I48: =IF(G48="","-",G48+H48) -> -
A49: 6 | H49: =IF(G49="","-",G49*$E$6) -> - | I49: =IF(G49="","-",G49+H49) -> -
A50: 7 | H50: =IF(G50="","-",G50*$E$6) -> - | I50: =IF(G50="","-",G50+H50) -> -
A51: 8 | H51: =IF(G51="","-",G51*$E$6) -> - | I51: =IF(G51="","-",G51+H51) -> -
...

Sheet Decembre
A1: RETOUR GAGNANT BENIN — REGISTRE FACTURES • DECEMBRE 2026
A2: IFU : 3202644573981 | RCCM : RB/COT/26 B 42001 | Haie-Vive Cocotiers, Carre 1158, Cotonou
A4: LEGENDE : Fond JAUNE = a SAISIR | Texte BLEU = valeur saisie | Texte NOIR = formule automatique
A6: PARAMETRE TVA (taux) : | E6: 0.18 | F6: Modifier si exoneration TVA (mettre 0%)
A8: SECTION 1 — RECETTES (ENTREES)
A9: N | B9: DATE | C9: N FACTURE / RECU | D9: CLIENT / BENEFICIAIRE | E9: CATEGORIE | F9: REF. DOSSIER | G9: MONTANT HT (FCFA) | H9: TVA (auto) | I9: TTC (auto) | J9: STATUT
A10: 1 | H10: =IF(G10="","-",G10*$E$6) -> - | I10: =IF(G10="","-",G10+H10) -> -
A11: 2 | H11: =IF(G11="","-",G11*$E$6) -> - | I11: =IF(G11="","-",G11+H11) -> -
A12: 3 | H12: =IF(G12="","-",G12*$E$6) -> - | I12: =IF(G12="","-",G12+H12) -> -
A13: 4 | H13: =IF(G13="","-",G13*$E$6) -> - | I13: =IF(G13="","-",G13+H13) -> -
A14: 5 | H14: =IF(G14="","-",G14*$E$6) -> - | I14: =IF(G14="","-",G14+H14) -> -
A15: 6 | H15: =IF(G15="","-",G15*$E$6) -> - | I15: =IF(G15="","-",G15+H15) -> -
A16: 7 | H16: =IF(G16="","-",G16*$E$6) -> - | I16: =IF(G16="","-",G16+H16) -> -
A17: 8 | H17: =IF(G17="","-",G17*$E$6) -> - | I17: =IF(G17="","-",G17+H17) -> -
A18: 9 | H18: =IF(G18="","-",G18*$E$6) -> - | I18: =IF(G18="","-",G18+H18) -> -
A19: 10 | H19: =IF(G19="","-",G19*$E$6) -> - | I19: =IF(G19="","-",G19+H19) -> -
A20: 11 | H20: =IF(G20="","-",G20*$E$6) -> - | I20: =IF(G20="","-",G20+H20) -> -
A21: 12 | H21: =IF(G21="","-",G21*$E$6) -> - | I21: =IF(G21="","-",G21+H21) -> -
... A27: 18 | H27: =IF(G27="","-",G27*$E$6) -> - | I27: =IF(G27="","-",G27+H27) -> -
A28: SOUS-TOTAL RECETTES DU MOIS | G28: =SUM(G10:G27) -> 0 | H28: =SUM(H10:H27) -> 0 | I28: =SUM(I10:I27) -> 0
A30: VENTILATION RECETTES PAR CATEGORIE
A31: CATEGORIE | E31: NB FAC. | F31: TOTAL HT | H31: TOTAL TTC | J31: % TOTAL
A32: Accompagnement diaspora | E32: =COUNTIF(E10:E27,A32) -> 0 | F32: =SUMIF(E10:E27,A32,G10:G27) -> 0 | H32: =SUMIF(E10:E27,A32,I10:I27) -> 0 | J32: =IFERROR(F32/G28,0) -> 0
A33: Ceremonie du Nom | E33: =COUNTIF(E10:E27,A33) -> 0 | F33: =SUMIF(E10:E27,A33,G10:G27) -> 0 | H33: =SUMIF(E10:E27,A33,I10:I27) -> 0 | J33: =IFERROR(F33/G28,0) -> 0
A34: Commission partenaire | E34: =COUNTIF(E10:E27,A34) -> 0 | F34: =SUMIF(E10:E27,A34,G10:G27) -> 0 | H34: =SUMIF(E10:E27,A34,I10:I27) -> 0 | J34: =IFERROR(F34/G28,0) -> 0
A35: Partenariat institutionnel | E35: =COUNTIF(E10:E27,A35) -> 0 | F35: =SUMIF(E10:E27,A35,G10:G27) -> 0 | H35: =SUMIF(E10:E27,A35,I10:I27) -> 0 | J35: =IFERROR(F35/G28,0) -> 0
A36: Formation / Atelier | E36: =COUNTIF(E10:E27,A36) -> 0 | F36: =SUMIF(E10:E27,A36,G10:G27) -> 0 | H36: =SUMIF(E10:E27,A36,I10:I27) -> 0 | J36: =IFERROR(F36/G28,0) -> 0
A37: Location / Prestation | E37: =COUNTIF(E10:E27,A37) -> 0 | F37: =SUMIF(E10:E27,A37,G10:G27) -> 0 | H37: =SUMIF(E10:E27,A37,I10:I27) -> 0 | J37: =IFERROR(F37/G28,0) -> 0
A38: Subvention / Aide | E38: =COUNTIF(E10:E27,A38) -> 0 | F38: =SUMIF(E10:E27,A38,G10:G27) -> 0 | H38: =SUMIF(E10:E27,A38,I10:I27) -> 0 | J38: =IFERROR(F38/G28,0) -> 0
A39: Autre recette | E39: =COUNTIF(E10:E27,A39) -> 0 | F39: =SUMIF(E10:E27,A39,G10:G27) -> 0 | H39: =SUMIF(E10:E27,A39,I10:I27) -> 0 | J39: =IFERROR(F39/G28,0) -> 0
A42: SECTION 2 — DEPENSES (SORTIES)
A43: N | B43: DATE | C43: N FACTURE / RECU | D43: FOURNISSEUR | E43: CATEGORIE | F43: REF. | G43: MONTANT HT (FCFA) | H43: TVA (auto) | I43: TTC (auto) | J43: STATUT
A44: 1 | H44: =IF(G44="","-",G44*$E$6) -> - | I44: =IF(G44="","-",G44+H44) -> -
A45: 2 | H45: =IF(G45="","-",G45*$E$6) -> - | I45: =IF(G45="","-",G45+H45) -> -
A46: 3 | H46: =IF(G46="","-",G46*$E$6) -> - | I46: =IF(G46="","-",G46+H46) -> -
A47: 4 | H47: =IF(G47="","-",G47*$E$6) -> - | I47: =IF(G47="","-",G47+H47) -> -
A48: 5 | H48: =IF(G48="","-",G48*$E$6) -> - | I48: =IF(G48="","-",G48+H48) -> -
A49: 6 | H49: =IF(G49="","-",G49*$E$6) -> - | I49: =IF(G49="","-",G49+H49) -> -
A50: 7 | H50: =IF(G50="","-",G50*$E$6) -> - | I50: =IF(G50="","-",G50+H50) -> -
A51: 8 | H51: =IF(G51="","-",G51*$E$6) -> - | I51: =IF(G51="","-",G51+H51) -> -
...
